Workbook

Sheet Compliance Readiness Checklist
A1: COMPLIANCE READINESS CHECKLIST
A2: Assess Organizational Readiness to Identify, Manage, Monitor, and Respond to Regulatory Requirements | Forisa Abadijaya Sejahtera
A4: SCORING GUIDE: 1 = Not in place | 2 = Partially in place | 3 = Defined, needs improvement | 4 = Well established | 5 = Mature & continuously improved
A6: 01. REGULATORY IDENTIFICATION
A7: # | B7: Assessment Statement | C7: Score (1-5) | D7: Max | E7: Status / Notes
A8: 1 | B8: The organization has identified the laws and regulations relevant to its business activities. | D8: 5 | E8: =IF(C8>=4,"Established",IF(C8>=3,"Needs Work","Risk Area")) -> Risk Area
A9: 2 | B9: Regulatory requirements are mapped to the organization's business processes. | D9: 5 | E9: =IF(C9>=4,"Established",IF(C9>=3,"Needs Work","Risk Area")) -> Risk Area
A10: 3 | B10: Responsibility for monitoring regulatory developments is clearly assigned. | D10: 5 | E10: =IF(C10>=4,"Established",IF(C10>=3,"Needs Work","Risk Area")) -> Risk Area
A11: 4 | B11: Regulatory changes are monitored on a regular basis. | D11: 5 | E11: =IF(C11>=4,"Established",IF(C11>=3,"Needs Work","Risk Area")) -> Risk Area
A12: 5 | B12: The organization evaluates how regulatory changes may affect its operations. | D12: 5 | E12: =IF(C12>=4,"Established",IF(C12>=3,"Needs Work","Risk Area")) -> Risk Area
A13: 6 | B13: Applicable licenses, registrations, and permits are identified and documented. | D13: 5 | E13: =IF(C13>=4,"Established",IF(C13>=3,"Needs Work","Risk Area")) -> Risk Area
A14: 7 | B14: Regulatory obligations are reviewed when there are significant changes to the business. | D14: 5 | E14: =IF(C14>=4,"Established",IF(C14>=3,"Needs Work","Risk Area")) -> Risk Area
A15: 8 | B15: Management has visibility over significant regulatory obligations. | D15: 5 | E15: =IF(C15>=4,"Established",IF(C15>=3,"Needs Work","Risk Area")) -> Risk Area
B16: SECTION TOTAL | C16: =SUM(C8:C15) -> 0 | D16: =SUM(D8:D15) -> 40 | E16: =C16/D16 -> 0
A18: 02. COMPLIANCE RESPONSIBILITY & GOVERNANCE
A19: # | B19: Assessment Statement | C19: Score (1-5) | D19: Max | E19: Status / Notes
A20: 9 | B20: Compliance responsibilities are clearly assigned. | D20: 5 | E20: =IF(C20>=4,"Established",IF(C20>=3,"Needs Work","Risk Area")) -> Risk Area
A21: 10 | B21: Employees understand the compliance requirements relevant to their roles. | D21: 5 | E21: =IF(C21>=4,"Established",IF(C21>=3,"Needs Work","Risk Area")) -> Risk Area
A22: 11 | B22: Management provides clear direction regarding compliance expectations. | D22: 5 | E22: =IF(C22>=4,"Established",IF(C22>=3,"Needs Work","Risk Area")) -> Risk Area
A23: 12 | B23: Compliance issues can be escalated to the appropriate level of management. | D23: 5 | E23: =IF(C23>=4,"Established",IF(C23>=3,"Needs Work","Risk Area")) -> Risk Area
A24: 13 | B24: Compliance responsibilities are included in relevant job roles. | D24: 5 | E24: =IF(C24>=4,"Established",IF(C24>=3,"Needs Work","Risk Area")) -> Risk Area
A25: 14 | B25: There is clear accountability when compliance requirements are not fulfilled. | D25: 5 | E25: =IF(C25>=4,"Established",IF(C25>=3,"Needs Work","Risk Area")) -> Risk Area
A26: 15 | B26: Compliance is integrated into business decision-making. | D26: 5 | E26: =IF(C26>=4,"Established",IF(C26>=3,"Needs Work","Risk Area")) -> Risk Area
A27: 16 | B27: Compliance responsibilities do not depend solely on one individual. | D27: 5 | E27: =IF(C27>=4,"Established",IF(C27>=3,"Needs Work","Risk Area")) -> Risk Area
B28: SECTION TOTAL | C28: =SUM(C20:C27) -> 0 | D28: =SUM(D20:D27) -> 40 | E28: =C28/D28 -> 0
A30: 03. POLICIES & PROCEDURES
A31: # | B31: Assessment Statement | C31: Score (1-5) | D31: Max | E31: Status / Notes
A32: 17 | B32: Key compliance policies are formally documented. | D32: 5 | E32: =IF(C32>=4,"Established",IF(C32>=3,"Needs Work","Risk Area")) -> Risk Area
A33: 18 | B33: Policies are aligned with applicable requirements. | D33: 5 | E33: =IF(C33>=4,"Established",IF(C33>=3,"Needs Work","Risk Area")) -> Risk Area
A34: 19 | B34: Relevant procedures are documented and accessible to employees. | D34: 5 | E34: =IF(C34>=4,"Established",IF(C34>=3,"Needs Work","Risk Area")) -> Risk Area
A35: 20 | B35: Policies and procedures are reviewed periodically. | D35: 5 | E35: =IF(C35>=4,"Established",IF(C35>=3,"Needs Work","Risk Area")) -> Risk Area
A36: 21 | B36: Changes in regulations are reflected in relevant policies and procedures. | D36: 5 | E36: =IF(C36>=4,"Established",IF(C36>=3,"Needs Work","Risk Area")) -> Risk Area
A37: 22 | B37: Employees receive appropriate communication or training regarding important policies. | D37: 5 | E37: =IF(C37>=4,"Established",IF(C37>=3,"Needs Work","Risk Area")) -> Risk Area
A38: 23 | B38: Policy exceptions require appropriate authorization. | D38: 5 | E38: =IF(C38>=4,"Established",IF(C38>=3,"Needs Work","Risk Area")) -> Risk Area
A39: 24 | B39: Management monitors whether policies are actually implemented in practice. | D39: 5 | E39: =IF(C39>=4,"Established",IF(C39>=3,"Needs Work","Risk Area")) -> Risk Area
B40: SECTION TOTAL | C40: =SUM(C32:C39) -> 0 | D40: =SUM(D32:D39) -> 40 | E40: =C40/D40 -> 0
A42: 04. DOCUMENTATION & RECORD KEEPING
A43: # | B43: Assessment Statement | C43: Score (1-5) | D43: Max | E43: Status / Notes
A44: 25 | B44: Required compliance documents are properly maintained. | D44: 5 | E44: =IF(C44>=4,"Established",IF(C44>=3,"Needs Work","Risk Area")) -> Risk Area
A45: 26 | B45: Licenses, permits, certificates, and registrations are monitored for validity. | D45: 5 | E45: =IF(C45>=4,"Established",IF(C45>=3,"Needs Work","Risk Area")) -> Risk Area
...

Sheet Dashboard & Report
A1: COMPLIANCE READINESS EXECUTIVE DASHBOARD
A2: Compliance Readiness Summary & Module Breakdown
B4: TOTAL READINESS SCORE | D4: READINESS LEVEL | F4: OVERALL COMPLIANCE %
B5: ='Compliance Readiness Checklist'!C102 -> 0 | D5: =IF(B5>=256,"Strong Readiness",IF(B5>=192,"Developing Readiness",IF(B5>=128,"Needs Attention","High Exposure"))) -> High Exposure | F5: =B5/320 -> 0
A7: Compliance Area Breakdown | H7: Readiness Level Scale
A8: Module # | B8: Compliance Area | C8: Score | D8: Max | E8: % Achieved | F8: Readiness Status | H8: Score Range | I8: Readiness Level | J8: General Interpretation
A9: 01 | B9: REGULATORY IDENTIFICATION | C9: ='Compliance Readiness Checklist'!C16 -> 0 | D9: ='Compliance Readiness Checklist'!D16 -> 40 | E9: =C9/D9 -> 0 | F9: =IF(E9>=0.8,"Strong Readiness",IF(E9>=0.6,"Developing Readiness",IF(E9>=0.4,"Needs Attention","High Exposure"))) -> High Exposure | H9: 256 – 320 | I9: Strong Readiness | J9: Core compliance practices are generally established, documented, monitored, and consistently implemented.
A10: 02 | B10: COMPLIANCE RESPONSIBILITY & GOVERNANCE | C10: ='Compliance Readiness Checklist'!C28 -> 0 | D10: ='Compliance Readiness Checklist'!D28 -> 40 | E10: =C10/D10 -> 0 | F10: =IF(E10>=0.8,"Strong Readiness",IF(E10>=0.6,"Developing Readiness",IF(E10>=0.4,"Needs Attention","High Exposure"))) -> High Exposure | H10: 192 – 255 | I10: Developing Readiness | J10: Key compliance mechanisms exist, but several areas require stronger consistency, ownership, or monitoring.
A11: 03 | B11: POLICIES & PROCEDURES | C11: ='Compliance Readiness Checklist'!C40 -> 0 | D11: ='Compliance Readiness Checklist'!D40 -> 40 | E11: =C11/D11 -> 0 | F11: =IF(E11>=0.8,"Strong Readiness",IF(E11>=0.6,"Developing Readiness",IF(E11>=0.4,"Needs Attention","High Exposure"))) -> High Exposure | H11: 128 – 191 | I11: Needs Attention | J11: Significant compliance gaps may exist and should be prioritized based on regulatory and business impact.
A12: 04 | B12: DOCUMENTATION & RECORD KEEPING | C12: ='Compliance Readiness Checklist'!C52 -> 0 | D12: ='Compliance Readiness Checklist'!D52 -> 40 | E12: =C12/D12 -> 0 | F12: =IF(E12>=0.8,"Strong Readiness",IF(E12>=0.6,"Developing Readiness",IF(E12>=0.4,"Needs Attention","High Exposure"))) -> High Exposure | H12: 64 – 127 | I12: High Exposure | J12: Compliance practices may be largely reactive, fragmented, or dependent on individuals, creating significant potential exposure.
A13: 05 | B13: COMPLIANCE MONITORING | C13: ='Compliance Readiness Checklist'!C64 -> 0 | D13: ='Compliance Readiness Checklist'!D64 -> 40 | E13: =C13/D13 -> 0 | F13: =IF(E13>=0.8,"Strong Readiness",IF(E13>=0.6,"Developing Readiness",IF(E13>=0.4,"Needs Attention","High Exposure"))) -> High Exposure
A14: 06 | B14: EMPLOYEE & HR COMPLIANCE | C14: ='Compliance Readiness Checklist'!C76 -> 0 | D14: ='Compliance Readiness Checklist'!D76 -> 40 | E14: =C14/D14 -> 0 | F14: =IF(E14>=0.8,"Strong Readiness",IF(E14>=0.6,"Developing Readiness",IF(E14>=0.4,"Needs Attention","High Exposure"))) -> High Exposure
A15: 07 | B15: ETHICS, INTEGRITY & CONFLICT OF INTEREST | C15: ='Compliance Readiness Checklist'!C88 -> 0 | D15: ='Compliance Readiness Checklist'!D88 -> 40 | E15: =C15/D15 -> 0 | F15: =IF(E15>=0.8,"Strong Readiness",IF(E15>=0.6,"Developing Readiness",IF(E15>=0.4,"Needs Attention","High Exposure"))) -> High Exposure
A16: 08 | B16: INCIDENT RESPONSE & CONTINUOUS IMPROVEMENT | C16: ='Compliance Readiness Checklist'!C100 -> 0 | D16: ='Compliance Readiness Checklist'!D100 -> 40 | E16: =C16/D16 -> 0 | F16: =IF(E16>=0.8,"Strong Readiness",IF(E16>=0.6,"Developing Readiness",IF(E16>=0.4,"Needs Attention","High Exposure"))) -> High Exposure

Sheet Action Roadmap
A1: COMPLIANCE ROADMAP & MANAGEMENT REFLECTION
A3: MANAGEMENT REFLECTION QUESTIONS
A4: # | B4: Management Reflection Question | C4: Context & Focus Area | D4: Management Assessment & Discussion Notes
A5: 1 | B5: What are our most critical compliance obligations? | C5: Identify requirements that could have the greatest impact if not fulfilled. | D5: [ Enter management reflection notes here ]
A6: 2 | B6: Which requirements do we have difficulty demonstrating? | C6: Ensure the organization can provide appropriate evidence when required. | D6: [ Enter management reflection notes here ]
A7: 3 | B7: Where are compliance responsibilities unclear? | C7: Identify obligations that do not have a clearly assigned owner. | D7: [ Enter management reflection notes here ]
A8: 4 | B8: Which compliance processes depend too heavily on individuals? | C8: Ensure compliance system continues to function when key personnel change. | D8: [ Enter management reflection notes here ]
A9: 5 | B9: What happens when a compliance issue is identified? | C9: Assess clarity of escalation, investigation, corrective action, and follow-up. | D9: [ Enter management reflection notes here ]
A12: FROM COMPLIANCE CHECK TO ACTION: IMPROVEMENT ROADMAP
A13: Requirement | B13: Compliance Gap | C13: Risk / Impact | D13: Root Cause | E13: Corrective Action | F13: Responsible Owner | G13: Deadline | H13: Evidence of Completion
A14: Permit & License Renewal Monitoring | B14: Unmonitored operational licenses expiry | C14: Fines & operational shutdown risk | D14: Lack of central tracking register | E14: Establish Automated Permit Register & alerts | F14: Legal Compliance | G14: Q1 2027 | H14: Active License Dashboard
A15: Data Privacy Compliance | B15: Unclear employee consent documentation | C15: Regulatory breach & legal exposure | D15: Outdated HR onboarding checklists | E15: Update HR Onboarding SOP & Privacy Consent | F15: HR Lead | G15: Q2 2027 | H15: Signed Consents in Files
A16: Whistleblowing & Incident Logging | B16: No formal channel to report misconduct | C16: Unresolved ethical risks & culture impact | D16: Absence of secure reporting system | E16: Launch Misconduct Reporting Portal & SOP | F16: Internal Audit | G16: Q1 2027 | H16: SOP & Portal Live
A17: Regulatory Change Tracking | B17: Ad-hoc monitoring of new business laws | C17: Non-compliance with updated mandates | D17: No designated regulatory monitor | E17: Assign regulatory monitor & quarterly review | F17: Compliance Officer | G17: Q2 2027 | H17: Quarterly Reg Report

Sheet FAS Perspective & Support
A1: FORISA ABADIJAYA SEHASTERA (FAS) - PERSPECTIVE & SERVICES
A3: “Compliance is not simply about avoiding violations. It is about building an organization that understands its obligations, manages its risks, maintains evidence, and consistently acts with integrity. Can we demonstrate that compliance actually works in practice?”
A6: NEED A DEEPER COMPLIANCE ASSESSMENT? HOW FAS CAN HELP:
A7: # | B7: Service Area | C7: Description & Value Add
A8: 1 | B8: Compliance Readiness Assessment | C8: Comprehensive assessment of your compliance baseline, gap identification, and readiness level.
A9: 2 | B9: Regulatory Requirement Mapping | C9: Mapping applicable laws, regulations, and industry standards to operational business processes.
A10: 3 | B10: Compliance Governance Framework | C10: Designing governance structures, clear roles, and escalation mechanisms for compliance oversight.
A11: 4 | B11: Policy & SOP Review | C11: Evaluating, updating, and aligning internal policies and procedures with regulatory mandates.
A12: 5 | B12: Compliance Monitoring Framework | C12: Building periodic monitoring, tracking, and reporting frameworks for management visibility.
A13: 6 | B13: Risk & Control Assessment | C13: Identifying compliance-related operational risks and designing internal controls to mitigate exposures.
A14: 7 | B14: HR & Employment Compliance Review | C14: Auditing employment agreements, working hours, statutory obligations, and workplace rules.
A15: 8 | B15: Compliance Improvement Roadmap | C15: Formulating actionable, prioritized improvement plans to address compliance gaps effectively.
A16: 9 | B16: Governance, Risk & Compliance (GRC) Integration | C16: Embedding compliance into enterprise governance, risk management, and business decision-making.
A19: FORISA ABADIJAYA SEHASTERA — Governance. People. Performance. Impact.
