Workbook

Sheet HR Health Check
A1: HR HEALTH CHECK - SELF-ASSESSMENT TOOL
A2: Evaluate the effectiveness, consistency, and governance of your HR function | Forisa Abadijaya Sejahtera
A4: SCORING GUIDE: 1 = Not in place | 2 = Partially in place | 3 = In place, needs improvement | 4 = Well implemented | 5 = Mature & continuously improved
A6: 01. ORGANIZATION & HR GOVERNANCE
A7: # | B7: Assessment Statement | C7: Score (1-5) | D7: Max | E7: Status / Notes
A8: 1 | B8: Organizational structure and reporting lines are clearly defined. | C8: 4 | D8: 5 | E8: =IF(C8>=4,"Strong",IF(C8>=3,"Moderate","Needs Focus"))
A9: 2 | B9: Every position has clearly defined responsibilities and authority. | C9: 4 | D9: 5 | E9: =IF(C9>=4,"Strong",IF(C9>=3,"Moderate","Needs Focus"))
A10: 3 | B10: There is no significant overlap or gap in responsibilities between positions. | C10: 2 | D10: 5 | E10: =IF(C10>=4,"Strong",IF(C10>=3,"Moderate","Needs Focus"))
A11: 4 | B11: Management has clearly defined who can make which decisions. | C11: 4 | D11: 5 | E11: =IF(C11>=4,"Strong",IF(C11>=3,"Moderate","Needs Focus"))
A12: 5 | B12: HR policies are formally documented and communicated to employees. | C12: 4 | D12: 5 | E12: =IF(C12>=4,"Strong",IF(C12>=3,"Moderate","Needs Focus"))
A13: 6 | B13: HR decisions are based on consistent policies rather than individual preferences. | C13: 2 | D13: 5 | E13: =IF(C13>=4,"Strong",IF(C13>=3,"Moderate","Needs Focus"))
A14: 7 | B14: There is a clear escalation mechanism for employee and management issues. | C14: 4 | D14: 5 | E14: =IF(C14>=4,"Strong",IF(C14>=3,"Moderate","Needs Focus"))
A15: 8 | B15: HR information is properly documented and accessible to authorized management. | C15: 4 | D15: 5 | E15: =IF(C15>=4,"Strong",IF(C15>=3,"Moderate","Needs Focus"))
B16: SECTION TOTAL | C16: =SUM(C8:C15) | D16: =SUM(D8:D15) | E16: =C16/D16
A18: 02. WORKFORCE PLANNING
A19: # | B19: Assessment Statement | C19: Score (1-5) | D19: Max | E19: Status / Notes
A20: 9 | B20: The organization knows how many employees are required for each function. | C20: 2 | D20: 5 | E20: =IF(C20>=4,"Strong",IF(C20>=3,"Moderate","Needs Focus"))
A21: 10 | B21: Manpower requirements are linked to business targets and workload. | C21: 4 | D21: 5 | E21: =IF(C21>=4,"Strong",IF(C21>=3,"Moderate","Needs Focus"))
A22: 11 | B22: The organization regularly reviews manpower productivity. | C22: 4 | D22: 5 | E22: =IF(C22>=4,"Strong",IF(C22>=3,"Moderate","Needs Focus"))
A23: 12 | B23: Critical positions have identified backup or succession plans. | C23: 2 | D23: 5 | E23: =IF(C23>=4,"Strong",IF(C23>=3,"Moderate","Needs Focus"))
A24: 13 | B24: Employee turnover is monitored and analyzed. | C24: 4 | D24: 5 | E24: =IF(C24>=4,"Strong",IF(C24>=3,"Moderate","Needs Focus"))
A25: 14 | B25: Absenteeism and attendance patterns are regularly reviewed. | C25: 4 | D25: 5 | E25: =IF(C25>=4,"Strong",IF(C25>=3,"Moderate","Needs Focus"))
A26: 15 | B26: Workforce costs are monitored against business performance. | C26: 2 | D26: 5 | E26: =IF(C26>=4,"Strong",IF(C26>=3,"Moderate","Needs Focus"))
A27: 16 | B27: Management has reliable data to support manpower decisions. | C27: 4 | D27: 5 | E27: =IF(C27>=4,"Strong",IF(C27>=3,"Moderate","Needs Focus"))
B28: SECTION TOTAL | C28: =SUM(C20:C27) | D28: =SUM(D20:D27) | E28: =C28/D28
A30: 03. RECRUITMENT & SELECTION
A31: # | B31: Assessment Statement | C31: Score (1-5) | D31: Max | E31: Status / Notes
A32: 17 | B32: Each position has clearly defined job requirements. | C32: 4 | D32: 5 | E32: =IF(C32>=4,"Strong",IF(C32>=3,"Moderate","Needs Focus"))
A33: 18 | B33: Recruitment criteria are based on actual job requirements. | C33: 2 | D33: 5 | E33: =IF(C33>=4,"Strong",IF(C33>=3,"Moderate","Needs Focus"))
A34: 19 | B34: Candidates are assessed using a consistent selection process. | C34: 4 | D34: 5 | E34: =IF(C34>=4,"Strong",IF(C34>=3,"Moderate","Needs Focus"))
A35: 20 | B35: Interviews evaluate both technical capability and behavioral fit. | C35: 4 | D35: 5 | E35: =IF(C35>=4,"Strong",IF(C35>=3,"Moderate","Needs Focus"))
A36: 21 | B36: Recruitment results are evaluated after employees join. | C36: 2 | D36: 5 | E36: =IF(C36>=4,"Strong",IF(C36>=3,"Moderate","Needs Focus"))
A37: 22 | B37: The organization tracks recruitment success and early turnover. | C37: 4 | D37: 5 | E37: =IF(C37>=4,"Strong",IF(C37>=3,"Moderate","Needs Focus"))
A38: 23 | B38: Hiring decisions are supported by documented assessment results. | C38: 4 | D38: 5 | E38: =IF(C38>=4,"Strong",IF(C38>=3,"Moderate","Needs Focus"))
A39: 24 | B39: Recruitment channels are evaluated based on quality of candidates, not only volume. | C39: 2 | D39: 5 | E39: =IF(C39>=4,"Strong",IF(C39>=3,"Moderate","Needs Focus"))
B40: SECTION TOTAL | C40: =SUM(C32:C39) | D40: =SUM(D32:D39) | E40: =C40/D40
A42: 04. PERFORMANCE MANAGEMENT
A43: # | B43: Assessment Statement | C43: Score (1-5) | D43: Max | E43: Status / Notes
A44: 25 | B44: Employees have clearly defined performance expectations. | C44: 4 | D44: 5 | E44: =IF(C44>=4,"Strong",IF(C44>=3,"Moderate","Needs Focus"))
A45: 26 | B45: KPIs are linked to organizational and departmental objectives. | C45: 4 | D45: 5 | E45: =IF(C45>=4,"Strong",IF(C45>=3,"Moderate","Needs Focus"))
...

Sheet Dashboard & Report
A1: HR HEALTH EXECUTIVE DASHBOARD
A2: Overall Performance Summary & Section Breakdown
B4: TOTAL HR HEALTH SCORE | D4: HEALTH LEVEL | F4: OVERALL COMPLIANCE %
B5: ='HR Health Check'!C102 | D5: =IF(B5>=256,"Strong Foundation",IF(B5>=192,"Developing",IF(B5>=128,"Needs Attention","High Risk"))) | F5: =B5/320
A7: Section Breakdown | H7: Score Interpretation Scale
A8: Section # | B8: HR Function Area | C8: Score | D8: Max | E8: % Achieved | F8: Status Level | H8: Score Range | I8: Health Level | J8: Interpretation & Guidance
A9: 01 | B9: ORGANIZATION & HR GOVERNANCE | C9: ='HR Health Check'!C16 | D9: ='HR Health Check'!D16 | E9: =C9/D9 | F9: =IF(E9>=0.8,"Strong",IF(E9>=0.6,"Developing",IF(E9>=0.4,"Needs Attention","High Risk"))) | H9: 256 – 320 | I9: Strong Foundation | J9: Core HR systems are generally established and functioning. Focus on optimization and continuous improvement.
A10: 02 | B10: WORKFORCE PLANNING | C10: ='HR Health Check'!C28 | D10: ='HR Health Check'!D28 | E10: =C10/D10 | F10: =IF(E10>=0.8,"Strong",IF(E10>=0.6,"Developing",IF(E10>=0.4,"Needs Attention","High Risk"))) | H10: 192 – 255 | I10: Developing | J10: Important HR systems exist, but several areas require strengthening and greater consistency.
A11: 03 | B11: RECRUITMENT & SELECTION | C11: ='HR Health Check'!C40 | D11: ='HR Health Check'!D40 | E11: =C11/D11 | F11: =IF(E11>=0.8,"Strong",IF(E11>=0.6,"Developing",IF(E11>=0.4,"Needs Attention","High Risk"))) | H11: 128 – 191 | I11: Needs Attention | J11: Significant gaps may be affecting people management, operational consistency, or business performance.
A12: 04 | B12: PERFORMANCE MANAGEMENT | C12: ='HR Health Check'!C52 | D12: ='HR Health Check'!D52 | E12: =C12/D12 | F12: =IF(E12>=0.8,"Strong",IF(E12>=0.6,"Developing",IF(E12>=0.4,"Needs Attention","High Risk"))) | H12: 64 – 127 | I12: High Risk | J12: HR practices may be largely reactive and expose the organization to operational, people, and compliance risks.
A13: 05 | B13: COMPENSATION & REWARD | C13: ='HR Health Check'!C64 | D13: ='HR Health Check'!D64 | E13: =C13/D13 | F13: =IF(E13>=0.8,"Strong",IF(E13>=0.6,"Developing",IF(E13>=0.4,"Needs Attention","High Risk")))
A14: 06 | B14: EMPLOYEE RELATIONS & CULTURE | C14: ='HR Health Check'!C76 | D14: ='HR Health Check'!D76 | E14: =C14/D14 | F14: =IF(E14>=0.8,"Strong",IF(E14>=0.6,"Developing",IF(E14>=0.4,"Needs Attention","High Risk")))
A15: 07 | B15: HR COMPLIANCE & RISK | C15: ='HR Health Check'!C88 | D15: ='HR Health Check'!D88 | E15: =C15/D15 | F15: =IF(E15>=0.8,"Strong",IF(E15>=0.6,"Developing",IF(E15>=0.4,"Needs Attention","High Risk")))
A16: 08 | B16: HR DATA & DECISION SUPPORT | C16: ='HR Health Check'!C100 | D16: ='HR Health Check'!D100 | E16: =C16/D16 | F16: =IF(E16>=0.8,"Strong",IF(E16>=0.6,"Developing",IF(E16>=0.4,"Needs Attention","High Risk")))

Sheet Action Roadmap
A1: HR IMPROVEMENT ROADMAP & MANAGEMENT ACTION
A3: THE 5 QUESTIONS MANAGEMENT SHOULD ASK
A4: # | B4: Management Discussion Question | C4: Context & Focus Area | D4: Management Assessment & Notes
A5: 1 | B5: Where is our biggest HR gap? | C5: Which section received the lowest score? Focus immediate assessment here. | D5: [ Enter management notes here ]
A6: 2 | B6: Which HR issue is already affecting business performance? | C6: Don't focus only on HR symptoms. Identify direct impact on revenue, cost, or execution. | D6: [ Enter management notes here ]
A7: 3 | B7: Which HR process depends too heavily on individual people? | C7: Identify key-person dependency. If one HR person or manager leaves, does the system work? | D7: [ Enter management notes here ]
A8: 4 | B8: Which HR policy exists on paper but is not consistently implemented? | C8: A policy that is not consistently practiced is a major governance weakness. | D8: [ Enter management notes here ]
A9: 5 | B9: What should we fix first? | C9: Prioritize issues based on business impact, risk level, and implementation urgency. | D9: [ Enter management notes here ]
A12: HR IMPROVEMENT ROADMAP (ACTION PLAN)
A13: Priority Issue | B13: Root Cause | C13: Business Impact | D13: Required Action | E13: Owner | F13: Timeline | G13: Success Measure
A14: Unclear job responsibilities | B14: Lack of formal job descriptions | C14: Overlap in duties & decision delays | D14: Develop & review standard Job Descriptions for all roles | E14: HR Manager | F14: Q1 2027 | G14: 100% signed JDs
A15: High turnover in key roles | B15: Competitive salary & vague career path | C15: High recruitment cost & lost productivity | D15: Conduct salary bench-marking & define career progression | E15: HR Director | F15: Q2 2027 | G15: Turnover rate < 10%
A16: Inconsistent Performance Feedback | B16: Managers lack appraisal coaching | C16: Low employee engagement & unclear KPIs | D16: Conduct KPI setting workshop & manager coaching | E16: OD Specialist | F16: Q1 2027 | G16: Bi-annual review compliance > 95%
A17: Paper-only HR Policies | B17: Policies not integrated into daily Ops | C17: Governance risk & inconsistent compliance | D17: Publish HR Handbook & run policy orientation sessions | E17: HR Ops Lead | F17: Q2 2027 | G17: Policy acknowledgment score 100%

Sheet FAS Perspective & Support
A1: FORISA ABADIJAYA SEHASTERA (FAS) - PERSPECTIVE & SERVICES
A3: “HR should not operate as an administrative function isolated from the business. A healthy HR function creates clarity in roles, consistency in decisions, accountability in performance, and discipline in organizational execution.”
A6: NEED A DEEPER ASSESSMENT? HOW FAS CAN HELP:
A7: # | B7: Service Area | C7: Description & Value Add
A8: 1 | B8: HR & Organizational Health Assessment | C8: Comprehensive diagnostic of your HR architecture, culture, and compliance risks.
A9: 2 | B9: Organizational Structure Review | C9: Optimizing reporting lines, span of control, and eliminating operational redundancies.
A10: 3 | B10: KPI & Performance Management | C10: Designing balanced scorecard and objective KPI frameworks tied to business growth.
A11: 4 | B11: HR Policy & SOP Development | C11: Creating practical, compliant, and enforceable HR policies and operational procedures.
A12: 5 | B12: Governance & Accountability Framework | C12: Establishing governance structures that drive accountability and execution discipline.
A13: 6 | B13: Authority Matrix Development | C13: Defining clear decision-making rights (Delegation of Authority) across all management levels.
A14: 7 | B14: Leadership Alignment | C14: Aligning executive leadership around shared strategy, values, and management standards.
A15: 8 | B15: Organizational Effectiveness Improvement | C15: Transforming HR into a strategic business enabler for sustainable impact.
A18: FORISA ABADIJAYA SEHASTERA — Governance. People. Performance. Impact.
